<?xml version="1.0" ?>
<robot name="team_hunt_player" xmlns:xacro="http://ros.org/wiki/xacro">

<!--  Arguments-->
<!--Arguments are used as $(arg argument)-->
  <xacro:arg name="player_name" default="p_mrivadeneira"/>
  <xacro:arg name="player_color" default="Red"/>

<!--  Copy argument to properties so that they are visible in the included xacros-->
<!--  Properties are used as ${property}-->
  <xacro:property name="player_name" value="$(arg player_name)"/>
  <xacro:property name="player_color" value="$(arg player_color)"/>


<!--  Includes-->
  <xacro:include filename="$(find p_mrivadeneira_description)/urdf/properties.xacro"/>
<!--  <xacro:include filename="$(find turtlebot3_description)/urdf/turtlebot3_waffle_pi.gazebo.xacro"/>-->
  <xacro:include filename="$(find p_mrivadeneira_description)/urdf/p_mrivadeneira.gazebo.xacro"/>


<!-- +++++++++++++++++++++++++++++++++++++++ BASIC TURTLEBOT +++++++++++++++++++++++++++++++++++++++ -->


<!--  Define links and joints-->
  <link name="base_footprint"/>

  <joint name="base_joint" type="fixed">
    <parent link="base_footprint"/>
    <child link="base_link" />
    <origin xyz="0 0 0.010" rpy="0 0 0"/>
  </joint>

  <link name="base_link">
    <visual>
      <origin xyz="-0.064 0 0.0" rpy="0 0 0"/>
      <geometry>
        <mesh filename="package://turtlebot3_description/meshes/bases/waffle_pi_base.stl" scale="0.001 0.001 0.001"/>
      </geometry>
<!--      <material name="light_black"/>-->
      <material name="$(arg player_color)"/>
    </visual>

    <collision>
      <origin xyz="-0.064 0 0.047" rpy="0 0 0"/>
      <geometry>
        <box size="0.266 0.266 0.094"/>
      </geometry>
    </collision>

    <inertial>
      <origin xyz="0 0 0" rpy="0 0 0"/>
      <mass value="1.3729096e+00"/>
      <inertia ixx="8.7002718e-03" ixy="-4.7576583e-05" ixz="1.1160499e-04"
               iyy="8.6195418e-03" iyz="-3.5422299e-06"
               izz="1.4612727e-02" />
    </inertial>
  </link>

  <joint name="wheel_left_joint" type="continuous">
    <parent link="base_link"/>
    <child link="wheel_left_link"/>
    <origin xyz="0.0 0.144 0.023" rpy="-1.57 0 0"/>
    <axis xyz="0 0 1"/>
  </joint>

  <link name="wheel_left_link">
    <visual>
      <origin xyz="0 0 0" rpy="1.57 0 0"/>
      <geometry>
        <mesh filename="package://turtlebot3_description/meshes/wheels/left_tire.stl" scale="0.001 0.001 0.001"/>
      </geometry>
      <material name="dark"/>
     </visual>

    <collision>
      <origin xyz="0 0 0" rpy="0 0 0"/>
      <geometry>
        <cylinder length="0.018" radius="0.033"/>
      </geometry>
    </collision>

    <inertial>
      <origin xyz="0 0 0" />
      <mass value="2.8498940e-02" />
      <inertia ixx="1.1175580e-05" ixy="-4.2369783e-11" ixz="-5.9381719e-09"
               iyy="1.1192413e-05" iyz="-1.4400107e-11"
               izz="2.0712558e-05" />
      </inertial>
  </link>

  <joint name="wheel_right_joint" type="continuous">
    <parent link="base_link"/>
    <child link="wheel_right_link"/>
    <origin xyz="0.0 -0.144 0.023" rpy="-1.57 0 0"/>
    <axis xyz="0 0 1"/>
  </joint>

  <link name="wheel_right_link">
    <visual>
      <origin xyz="0 0 0" rpy="1.57 0 0"/>
      <geometry>
        <mesh filename="package://turtlebot3_description/meshes/wheels/right_tire.stl" scale="0.001 0.001 0.001"/>
      </geometry>
      <material name="dark"/>
    </visual>

    <collision>
      <origin xyz="0 0 0" rpy="0 0 0"/>
      <geometry>
        <cylinder length="0.018" radius="0.033"/>
      </geometry>
    </collision>

    <inertial>
      <origin xyz="0 0 0" />
      <mass value="2.8498940e-02" />
      <inertia ixx="1.1175580e-05" ixy="-4.2369783e-11" ixz="-5.9381719e-09"
               iyy="1.1192413e-05" iyz="-1.4400107e-11"
               izz="2.0712558e-05" />
      </inertial>
  </link>

  <joint name="caster_back_right_joint" type="fixed">
    <parent link="base_link"/>
    <child link="caster_back_right_link"/>
    <origin xyz="-0.177 -0.064 -0.004" rpy="-1.57 0 0"/>
  </joint>

  <link name="caster_back_right_link">
    <collision>
      <origin xyz="0 0.001 0" rpy="0 0 0"/>
      <geometry>
        <box size="0.030 0.009 0.020"/>
      </geometry>
    </collision>

    <inertial>
      <origin xyz="0 0 0" />
      <mass value="0.005" />
      <inertia ixx="0.001" ixy="0.0" ixz="0.0"
               iyy="0.001" iyz="0.0"
               izz="0.001" />
    </inertial>
  </link>

  <joint name="caster_back_left_joint" type="fixed">
    <parent link="base_link"/>
    <child link="caster_back_left_link"/>
    <origin xyz="-0.177 0.064 -0.004" rpy="-1.57 0 0"/>
  </joint>

  <link name="caster_back_left_link">
    <collision>
      <origin xyz="0 0.001 0" rpy="0 0 0"/>
      <geometry>
        <box size="0.030 0.009 0.020"/>
      </geometry>
    </collision>

    <inertial>
      <origin xyz="0 0 0" />
      <mass value="0.005" />
      <inertia ixx="0.001" ixy="0.0" ixz="0.0"
               iyy="0.001" iyz="0.0"
               izz="0.001" />
    </inertial>
  </link>

  <joint name="imu_joint" type="fixed">
    <parent link="base_link"/>
    <child link="imu_link"/>
    <origin xyz="0.0 0 0.068" rpy="0 0 0"/>
  </joint>

  <link name="imu_link"/>

  <joint name="scan_joint" type="fixed">
    <parent link="base_link"/>
    <child link="base_scan"/>
    <origin xyz="-0.064 0 0.122" rpy="0 0 0"/>
  </joint>

  <link name="base_scan">
    <visual>
      <origin xyz="0 0 0.0" rpy="0 0 0"/>
      <geometry>
        <mesh filename="package://turtlebot3_description/meshes/sensors/lds.stl" scale="0.001 0.001 0.001"/>
      </geometry>
      <material name="dark"/>
    </visual>

    <collision>
      <origin xyz="0.015 0 -0.0065" rpy="0 0 0"/>
      <geometry>
        <cylinder length="0.0315" radius="0.055"/>
      </geometry>
    </collision>

    <inertial>
      <mass value="0.114" />
      <origin xyz="0 0 0" />
      <inertia ixx="0.001" ixy="0.0" ixz="0.0"
               iyy="0.001" iyz="0.0"
               izz="0.001" />
    </inertial>
  </link>

  <joint name="camera_joint" type="fixed">
    <origin xyz="0.073 -0.011 0.084" rpy="0 0 0"/>
    <parent link="base_link"/>
    <child link="camera_link"/>
  </joint>

  <link name="camera_link">
    <collision>
      <origin xyz="0.005 0.011 0.013" rpy="0 0 0"/>
      <geometry>
        <box size="0.015 0.030 0.027"/>
      </geometry>
    </collision>
  </link>

  <joint name="camera_rgb_joint" type="fixed">
    <origin xyz="0.003 0.011 0.009" rpy="0 0 0"/>
    <parent link="camera_link"/>
    <child link="camera_rgb_frame"/>
  </joint>
  <link name="camera_rgb_frame"/>

  <joint name="camera_rgb_optical_joint" type="fixed">
    <origin xyz="0 0 0" rpy="-1.57 0 -1.57"/>
    <parent link="camera_rgb_frame"/>
    <child link="camera_rgb_optical_frame"/>
  </joint>
  <link name="camera_rgb_optical_frame"/>


<!--  &lt;!&ndash; +++++++++++++++++++++++++++++++++++++++ EXTRAS FOR TURTLEBOT +++++++++++++++++++++++++++++++++++++++ &ndash;&gt;-->

    <!--base_link to antenna-->
  <link name="antenna">
    <visual>
      <origin rpy="0 0 0" xyz="0 0 0"/>
      <geometry>
        <cylinder length="0.15" radius="0.005"/>
      </geometry>
      <material name="$(arg player_color)"/>
    </visual>
  </link>

  <joint name="base_link_to_antenna" type="fixed">
    <origin rpy="0 0 0" xyz="0.05 0 0.16"/>
    <parent link="base_link"/>
    <child link="antenna"/>
  </joint>


  <!--Right arm-->
  <link name="right_arm_base">
    <visual>
      <origin rpy="0 0 0" xyz="0 0 0"/>
      <geometry>
        <cylinder length="0.015" radius="0.02"/>
      </geometry>
      <material name="dark"/>
    </visual>
    <collision>
      <origin rpy="0 0 0" xyz="0 0 0"/>
      <geometry>
        <cylinder length="0.015" radius="0.02"/>
      </geometry>
    </collision>
    <inertial>
      <origin rpy="0 0 0" xyz="0 0 0"/>
      <mass value="0.005"/>
      <inertia
        ixx="0.001" ixy="0.0" ixz="0.0"
        iyy="0.001" iyz="0.0"
        izz="0.001"
      />
    </inertial>
  </link>

  <joint name="base_link_to_right_arm_base" type="fixed">
    <origin rpy="0 0 0" xyz="0.04 -0.095 0.0985"/>
    <parent link="base_link"/>
    <child link="right_arm_base"/>
  </joint>

    <link name="right_arm">
    <visual>
      <origin xyz="-0.1 0 0" rpy="0 0 0"/>
      <geometry>
        <box size="0.2 0.04 0.01"/>
      </geometry>
      <material name="dark"/>
    </visual>
    <collision>
      <origin xyz="-0.1 0 0" rpy="0 0 0"/>
      <geometry>
        <box size="0.2 0.04 0.01"/>
      </geometry>
    </collision>
    <inertial>
      <origin rpy="0 0 0" xyz="0 0 0"/>
      <mass value="0.005"/>
      <inertia
        ixx="0.001" ixy="0.0" ixz="0.0"
        iyy="0.001" iyz="0.0"
        izz="0.001"
      />
    </inertial>
  </link>

  <joint name="right_arm_base_to_right_arm" type="revolute">
    <axis xyz="0 0 1"/>
    <limit effort="1000.0" lower="0.0" upper="1.8" velocity="0.2"/>
    <origin rpy="0 0 0" xyz="0 0 0"/>
    <parent link="right_arm_base"/>
    <child link="right_arm"/>
    <dynamics damping="0.7" />
  </joint>


  <!--Right arm - Part 2-->
  <link name="right_arm_2_base">
    <visual>
      <origin rpy="0 0 0" xyz="0 0 0.005"/>
      <geometry>
        <cylinder length="0.02" radius="0.02"/>
      </geometry>
      <material name="dark"/>
    </visual>
    <collision>
      <origin rpy="0 0 0" xyz="0 0 0"/>
      <geometry>
        <cylinder length="0.02" radius="0.02"/>
      </geometry>
    </collision>
    <inertial>
      <origin rpy="0 0 0" xyz="0 0 0"/>
      <mass value="0.005"/>
      <inertia
        ixx="0.001" ixy="0.0" ixz="0.0"
        iyy="0.001" iyz="0.0"
        izz="0.001"
      />
    </inertial>
  </link>

  <joint name="right_arm_to_right_arm_2_base" type="fixed">
    <origin rpy="0 0 0" xyz="-0.2 0 0"/>
    <parent link="right_arm"/>
    <child link="right_arm_2_base"/>
  </joint>

    <link name="right_arm_2">
    <visual>
      <origin xyz="0.1 0 0" rpy="0 0 0"/>
      <geometry>
        <box size="0.2 0.04 0.01"/>
      </geometry>
      <material name="dark"/>
    </visual>
    <collision>
      <origin xyz="-0.1 0 0" rpy="0 0 0"/>
      <geometry>
        <box size="0.2 0.04 0.01"/>
      </geometry>
    </collision>
    <inertial>
      <origin rpy="0 0 0" xyz="0 0 0"/>
      <mass value="0.005"/>
      <inertia
        ixx="0.001" ixy="0.0" ixz="0.0"
        iyy="0.001" iyz="0.0"
        izz="0.001"
      />
    </inertial>
  </link>

  <joint name="right_arm_2_base_to_right_arm_2" type="revolute">
    <axis xyz="0 0 1"/>
    <limit effort="1000.0" lower="-6.5" upper="3.5" velocity="0.2"/>
    <origin rpy="0 0 0" xyz="0 0 0.01"/>
    <parent link="right_arm_2_base"/>
    <child link="right_arm_2"/>
    <dynamics damping="0.7" />
  </joint>

   <!--Left arm-->
  <link name="left_arm_base">
    <visual>
      <origin rpy="0 0 0" xyz="0 0 0"/>
      <geometry>
        <cylinder length="0.01" radius="0.02"/>
      </geometry>
      <material name="dark"/>
    </visual>
    <collision>
      <origin rpy="0 0 0" xyz="0 0 0"/>
      <geometry>
        <cylinder length="0.01" radius="0.02"/>
      </geometry>
    </collision>
    <inertial>
      <origin rpy="0 0 0" xyz="0 0 0"/>
      <mass value="0.005"/>
      <inertia
        ixx="0.001" ixy="0.0" ixz="0.0"
        iyy="0.001" iyz="0.0"
        izz="0.001"
      />
    </inertial>
  </link>

  <joint name="base_link_to_left_arm_base" type="fixed">
    <origin rpy="0 0 0" xyz="0.04 0.095 0.0985"/>
    <parent link="base_link"/>
    <child link="left_arm_base"/>
  </joint>

    <link name="left_arm">
    <visual>
      <origin xyz="-0.1 0 0" rpy="0 0 0"/>
      <geometry>
        <box size="0.2 0.04 0.01"/>
      </geometry>
      <material name="dark"/>
    </visual>
    <collision>
      <origin xyz="-0.1 0 0" rpy="0 0 0"/>
      <geometry>
        <box size="0.2 0.04 0.01"/>
      </geometry>
    </collision>
    <inertial>
      <origin rpy="0 0 0" xyz="0 0 0"/>
      <mass value="0.005"/>
      <inertia
        ixx="0.001" ixy="0.0" ixz="0.0"
        iyy="0.001" iyz="0.0"
        izz="0.001"
      />
    </inertial>
  </link>

    <joint name="left_arm_base_to_left_arm" type="revolute">
    <axis xyz="0 0 1"/>
    <limit effort="1000.0" lower="-1.8" upper="0.0" velocity="0.2"/>
    <origin rpy="0 0 0" xyz="0 0 0"/>
    <parent link="left_arm_base"/>
    <child link="left_arm"/>
    <dynamics damping="0.7" />
  </joint>

    <!--Left arm - Part 2-->
  <link name="left_arm_2_base">
    <visual>
      <origin rpy="0 0 0" xyz="0 0 0.005"/>
      <geometry>
        <cylinder length="0.02" radius="0.02"/>
      </geometry>
      <material name="dark"/>
    </visual>
    <collision>
      <origin rpy="0 0 0" xyz="0 0 0"/>
      <geometry>
        <cylinder length="0.02" radius="0.02"/>
      </geometry>
    </collision>
    <inertial>
      <origin rpy="0 0 0" xyz="0 0 0"/>
      <mass value="0.005"/>
      <inertia
        ixx="0.001" ixy="0.0" ixz="0.0"
        iyy="0.001" iyz="0.0"
        izz="0.001"
      />
    </inertial>
  </link>

  <joint name="left_arm_to_left_arm_2_base" type="fixed">
    <origin rpy="0 0 0" xyz="-0.2 0 0"/>
    <parent link="left_arm"/>
    <child link="left_arm_2_base"/>
  </joint>

    <link name="left_arm_2">
    <visual>
      <origin xyz="0.1 0 0" rpy="0 0 0"/>
      <geometry>
        <box size="0.2 0.04 0.01"/>
      </geometry>
      <material name="dark"/>
    </visual>
    <collision>
      <origin xyz="-0.1 0 0" rpy="0 0 0"/>
      <geometry>
        <box size="0.2 0.04 0.01"/>
      </geometry>
    </collision>
    <inertial>
      <origin rpy="0 0 0" xyz="0 0 0"/>
      <mass value="0.005"/>
      <inertia
        ixx="0.001" ixy="0.0" ixz="0.0"
        iyy="0.001" iyz="0.0"
        izz="0.001"
      />
    </inertial>
  </link>

  <joint name="left_arm_2_base_to_left_arm_2" type="revolute">
    <axis xyz="0 0 1"/>
    <limit effort="1000.0" lower="-3.5" upper="6.5" velocity="0.2"/>
    <origin rpy="0 0 0" xyz="0 0 0.01"/>
    <parent link="left_arm_2_base"/>
    <child link="left_arm_2"/>
    <dynamics damping="0.7" />
  </joint>

<!-- +++++++++++++++++++++++++++++++++++++++ Gazebo Related Part ++++++++++++++++++++++++++++++++++++++++++++ -->

<!--  ROS control plug-in for Gazebo-->
  <gazebo>
    <plugin name="gazebo_ros_control" filename="libgazebo_ros_control.so">
        <robotNamespace>/${player_name}</robotNamespace>
        <robotSimType>gazebo_ros_control/DefaultRobotHWSim</robotSimType>
        <robotParam>/${player_name}/robot_description</robotParam>
        <legacyModeNS>true</legacyModeNS>
    </plugin>
  </gazebo>

<!--  Transmission definition for arms-->
  <transmission name="right_arm_base_to_right_arm_transmission">
    <type>transmission_interface/SimpleTransmission</type>
    <joint name="right_arm_base_to_right_arm">
      <hardwareInterface>hardware_interface/EffortJointInterface</hardwareInterface>
    </joint>
    <actuator name="motor1">
      <hardwareInterface>hardware_interface/EffortJointInterface</hardwareInterface>
      <mechanicalReduction>1</mechanicalReduction>
    </actuator>
  </transmission>

    <transmission name="left_arm_base_to_left_arm_transmission">
    <type>transmission_interface/SimpleTransmission</type>
    <joint name="left_arm_base_to_left_arm">
      <hardwareInterface>hardware_interface/EffortJointInterface</hardwareInterface>
    </joint>
    <actuator name="motor2">
      <hardwareInterface>hardware_interface/EffortJointInterface</hardwareInterface>
      <mechanicalReduction>1</mechanicalReduction>
    </actuator>
  </transmission>

  <transmission name="right_arm_2_base_to_right_arm_2_transmission">
    <type>transmission_interface/SimpleTransmission</type>
    <joint name="right_arm_2_base_to_right_arm_2">
      <hardwareInterface>hardware_interface/EffortJointInterface</hardwareInterface>
    </joint>
    <actuator name="motor3">
      <hardwareInterface>hardware_interface/EffortJointInterface</hardwareInterface>
      <mechanicalReduction>1</mechanicalReduction>
    </actuator>
  </transmission>

  <transmission name="left_arm_2_base_to_left_arm_2_transmission">
    <type>transmission_interface/SimpleTransmission</type>
    <joint name="left_arm_2_base_to_left_arm_2">
      <hardwareInterface>hardware_interface/EffortJointInterface</hardwareInterface>
    </joint>
    <actuator name="motor4">
      <hardwareInterface>hardware_interface/EffortJointInterface</hardwareInterface>
      <mechanicalReduction>1</mechanicalReduction>
    </actuator>
  </transmission>

</robot>
